Workbook

Sheet 第一次月考
A1: 序号 | B1: 班级 | C1: 学号 | D1: 姓名 | E1: 性别 | F1: 选定组合 | G1: 考号 | H1: 物理六总 | I1: 市排名 | J1: 校排名 | K1: 物理四总 | L1: 市排名 | M1: 校排名 | N1: 语文 | O1: 市排名 | P1: 校排名 | Q1: 数学 | R1: 市排名 | S1: 校排名 | T1: 英语 | U1: 市排名 | V1: 校排名 | W1: 日语 | X1: 市排名 | Y1: 校排名 | Z1: 外语 | AA1: 外语校排 | AB1: 物理 | AC1: 市排名 | AD1: 校排名 | AE1: 化学原始 | AF1: 化赋 | AG1: 市排名 | AH1: 校排名 | AI1: 生物原始 | AJ1: 生赋 | AK1: 市排名 | AL1: 校排名 | AM1: 政治原始 | AN1: 政赋 | AO1: 市排名 | AP1: 校排名 | AQ1: 地理原始 | AR1: 地赋 | AS1: 市排名 | AT1: 校排名
A2: 379 | B2: 08 | C2: 08050101 | D2: 黄钰珊 | E2: 女 | F2: 物生地 | G2: 2005270801 | H2: 410.25 | I2: 10364 | J2: 495 | K2: =SUM(N2+Q2+T2+W2+AB2) -> 250.25 | L2: =VLOOKUP(G2,[1]物理类!$F:$Q,12,FALSE) -> 11322 | M2: =RANK(K2,K$2:K$916,0) -> 643 | N2: 112 | O2: 5002 | P2: =RANK(N2,N$2:N$9631,0) -> 90 | Q2: 64 | R2: 8801 | S2: 239 | T2: 36.25 | U2: 19538 | V2: 850 | Z2: =SUM(T2+W2) -> 36.25 | AA2: =RANK(Z2,Z$2:Z$9631,0) -> 908 | AB2: 38 | AC2: 10646 | AD2: 441 | AI2: 70 | AJ2: 85 | AK2: 1923 | AL2: 14 | AQ2: 72 | AR2: 75 | AS2: 5478 | AT2: 314
A3: 380 | B3: 08 | C3: 08051002 | D3: 杨锦滢 | E3: 女 | F3: 物生地 | G3: 2005270802 | H3: 412.38 | I3: 10257 | J3: 473 | K3: =SUM(N3+Q3+T3+W3+AB3) -> 260.38 | L3: =VLOOKUP(G3,[1]物理类!$F:$Q,12,FALSE) -> 10769 | M3: =RANK(K3,K$2:K$916,0) -> 552 | N3: 103.5 | O3: 11888 | P3: =RANK(N3,N$2:N$9631,0) -> 393 | Q3: 50 | R3: 12383 | S3: 453 | T3: 76.88 | U3: 13016 | V3: 458 | Z3: =SUM(T3+W3) -> 76.88 | AA3: =RANK(Z3,Z$2:Z$9631,0) -> 512 | AB3: 30 | AC3: 12137 | AD3: 653 | AI3: 59 | AJ3: 77 | AK3: 4706 | AL3: 125 | AQ3: 72 | AR3: 75 | AS3: 5478 | AT3: 314
A4: 381 | B4: 08 | C4: 08242603 | D4: 谢欣灵 | E4: 女 | F4: 物生地 | G4: 2005270803 | H4: 444.5 | I4: 8542 | J4: 235 | K4: =SUM(N4+Q4+T4+W4+AB4) -> 299.5 | L4: =VLOOKUP(G4,[1]物理类!$F:$Q,12,FALSE) -> 8359 | M4: =RANK(K4,K$2:K$916,0) -> 232 | N4: 117 | O4: 2103 | P4: =RANK(N4,N$2:N$9631,0) -> 23 | Q4: 48 | R4: 12936 | S4: 481 | T4: 92.5 | U4: 8522 | V4: 158 | Z4: =SUM(T4+W4) -> 92.5 | AA4: =RANK(Z4,Z$2:Z$9631,0) -> 193 | AB4: 42 | AC4: 9870 | AD4: 348 | AI4: 50 | AJ4: 72 | AK4: 6673 | AL4: 279 | AQ4: 71 | AR4: 73 | AS4: 5921 | AT4: 346
A5: 382 | B5: 08 | C5: 08141204 | D5: 谭殷蕾 | E5: 女 | F5: 物生地 | G5: 2005270804 | H5: 432.75 | I5: 9178 | J5: 321 | K5: =SUM(N5+Q5+T5+W5+AB5) -> 290.75 | L5: =VLOOKUP(G5,[1]物理类!$F:$Q,12,FALSE) -> 8923 | M5: =RANK(K5,K$2:K$916,0) -> 295 | N5: 103.5 | O5: 11888 | P5: =RANK(N5,N$2:N$9631,0) -> 393 | Q5: 70 | R5: 7359 | S5: 154 | T5: 66.25 | U5: 15619 | V5: 669 | Z5: =SUM(T5+W5) -> 66.25 | AA5: =RANK(Z5,Z$2:Z$9631,0) -> 727 | AB5: 51 | AC5: 7998 | AD5: 170 | AI5: 50 | AJ5: 72 | AK5: 6673 | AL5: 279 | AQ5: 68 | AR5: 70 | AS5: 7094 | AT5: 441
A6: 383 | B6: 08 | C6: 08233405 | D6: 李芷铭 | E6: 女 | F6: 物生地 | G6: 2005270805 | H6: 417.88 | I6: 9947 | J6: 430 | K6: =SUM(N6+Q6+T6+W6+AB6) -> 269.88 | L6: =VLOOKUP(G6,[1]物理类!$F:$Q,12,FALSE) -> 10212 | M6: =RANK(K6,K$2:K$916,0) -> 469 | N6: 104.5 | O6: 11039 | P6: =RANK(N6,N$2:N$9631,0) -> 356 | Q6: 55 | R6: 11089 | S6: 371 | T6: 69.38 | U6: 14913 | V6: 605 | Z6: =SUM(T6+W6) -> 69.38 | AA6: =RANK(Z6,Z$2:Z$9631,0) -> 661 | AB6: 41 | AC6: 10092 | AD6: 378 | AI6: 55 | AJ6: 75 | AK6: 5678 | AL6: 186 | AQ6: 71 | AR6: 73 | AS6: 5921 | AT6: 346
A7: 384 | B7: 08 | C7: 08060606 | D7: 刘倩巧 | E7: 女 | F7: 物生地 | G7: 2005270806 | H7: 439.25 | I7: 8824 | J7: 278 | K7: =SUM(N7+Q7+T7+W7+AB7) -> 285.25 | L7: =VLOOKUP(G7,[1]物理类!$F:$Q,12,FALSE) -> 9269 | M7: =RANK(K7,K$2:K$916,0) -> 338 | N7: 106.5 | O7: 9392 | P7: =RANK(N7,N$2:N$9631,0) -> 259 | Q7: 41 | R7: 14746 | S7: 622 | T7: 88.75 | U7: 9624 | V7: 211 | Z7: =SUM(T7+W7) -> 88.75 | AA7: =RANK(Z7,Z$2:Z$9631,0) -> 251 | AB7: 49 | AC7: 8412 | AD7: 198 | AI7: 62 | AJ7: 79 | AK7: 3903 | AL7: 69 | AQ7: 72 | AR7: 75 | AS7: 5478 | AT7: 314
A8: 385 | B8: 08 | C8: 08223607 | D8: 梁紫宜 | E8: 女 | F8: 物生地 | G8: 2005270807 | H8: 404.75 | I8: 10631 | J8: 535 | K8: =SUM(N8+Q8+T8+W8+AB8) -> 271.75 | L8: =VLOOKUP(G8,[1]物理类!$F:$Q,12,FALSE) -> 10085 | M8: =RANK(K8,K$2:K$916,0) -> 452 | N8: 101.5 | O8: 13507 | P8: =RANK(N8,N$2:N$9631,0) -> 476 | Q8: 48 | R8: 12936 | S8: 481 | T8: 76.25 | U8: 13173 | V8: 471 | Z8: =SUM(T8+W8) -> 76.25 | AA8: =RANK(Z8,Z$2:Z$9631,0) -> 525 | AB8: 46 | AC8: 9052 | AD8: 261 | AI8: 41 | AJ8: 66 | AK8: 8684 | AL8: 507 | AQ8: 65 | AR8: 67 | AS8: 8036 | AT8: 502
A9: 386 | B9: 08 | C9: 08121708 | D9: 李咏恩 | E9: 女 | F9: 物生地 | G9: 2005270808 | H9: 395.88 | I9: 11057 | J9: 599 | K9: =SUM(N9+Q9+T9+W9+AB9) -> 241.88 | L9: =VLOOKUP(G9,[1]物理类!$F:$Q,12,FALSE) -> 11755 | M9: =RANK(K9,K$2:K$916,0) -> 712 | N9: 107.5 | O9: 8551 | P9: =RANK(N9,N$2:N$9631,0) -> 228 | Q9: 43 | R9: 14226 | S9: 583 | T9: 59.38 | U9: 17022 | V9: 755 | Z9: =SUM(T9+W9) -> 59.38 | AA9: =RANK(Z9,Z$2:Z$9631,0) -> 813 | AB9: 32 | AC9: 11800 | AD9: 607 | AI9: 66 | AJ9: 82 | AK9: 2956 | AL9: 36 | AQ9: 70 | AR9: 72 | AS9: 6342 | AT9: 385
A10: 387 | B10: 08 | C10: 08201109 | D10: 甘丽华 | E10: 女 | F10: 物生地 | G10: 2005270809 | H10: 473.63 | I10: 6848 | J10: 107 | K10: =SUM(N10+Q10+T10+W10+AB10) -> 310.63 | L10: =VLOOKUP(G10,[1]物理类!$F:$Q,12,FALSE) -> 7574 | M10: =RANK(K10,K$2:K$916,0) -> 161 | N10: 99.5 | O10: 14955 | P10: =RANK(N10,N$2:N$9631,0) -> 575 | Q10: 86 | R10: 3668 | S10: 44 | T10: 78.13 | U10: 12671 | V10: 426 | Z10: =SUM(T10+W10) -> 78.13 | AA10: =RANK(Z10,Z$2:Z$9631,0) -> 478 | AB10: 47 | AC10: 8842 | AD10: 239 | AI10: 53 | AJ10: 74 | AK10: 5937 | AL10: 211 | AQ10: 86 | AR10: 89 | AS10: 329 | AT10: 4
A11: 388 | B11: 08 | C11: 08092710 | D11: 覃建鹏 | E11: 男 | F11: 物生地 | G11: 2005270810 | H11: 380.63 | I11: 11755 | J11: 706 | K11: =SUM(N11+Q11+T11+W11+AB11) -> 241.63 | L11: =VLOOKUP(G11,[1]物理类!$F:$Q,12,FALSE) -> 11764 | M11: =RANK(K11,K$2:K$916,0) -> 714 | N11: 100.5 | O11: 14261 | P11: =RANK(N11,N$2:N$9631,0) -> 527 | Q11: 33 | R11: 16960 | S11: 740 | T11: 88.13 | U11: 9801 | V11: 219 | Z11: =SUM(T11+W11) -> 88.13 | AA11: =RANK(Z11,Z$2:Z$9631,0) -> 261 | AB11: 20 | AC11: 13637 | AD11: 850 | AI11: 41 | AJ11: 66 | AK11: 8684 | AL11: 507 | AQ11: 71 | AR11: 73 | AS11: 5921 | AT11: 346
A12: 389 | B12: 08 | C12: 08072811 | D12: 林婧恩 | E12: 女 | F12: 物生地 | G12: 2005270811 | H12: 364 | I12: 12423 | J12: 787 | K12: =SUM(N12+Q12+T12+W12+AB12) -> 232 | L12: =VLOOKUP(G12,[1]物理类!$F:$Q,12,FALSE) -> 12180 | M12: =RANK(K12,K$2:K$916,0) -> 772 | N12: 89 | O12: 19656 | P12: =RANK(N12,N$2:N$9631,0) -> 853 | Q12: 55 | R12: 11089 | S12: 371 | T12: 65 | U12: 15898 | V12: 689 | Z12: =SUM(T12+W12) -> 65 | AA12: =RANK(Z12,Z$2:Z$9631,0) -> 747 | AB12: 23 | AC12: 13250 | AD12: 812 | AI12: 37 | AJ12: 64 | AK12: 9144 | AL12: 559 | AQ12: 66 | AR12: 68 | AS12: 7744 | AT12: 481
A13: 390 | B13: 08 | C13: 08070412 | D13: 钟晋杰 | E13: 男 | F13: 物生地 | G13: 2005270812 | H13: 374.88 | I13: 12003 | J13: 737 | K13: =SUM(N13+Q13+T13+W13+AB13) -> 238.88 | L13: =VLOOKUP(G13,[1]物理类!$F:$Q,12,FALSE) -> 11890 | M13: =RANK(K13,K$2:K$916,0) -> 732 | N13: 101.5 | O13: 13507 | P13: =RANK(N13,N$2:N$9631,0) -> 476 | Q13: 18 | R13: 20407 | S13: 885 | T13: 94.38 | U13: 7967 | V13: 135 | Z13: =SUM(T13+W13) -> 94.38 | AA13: =RANK(Z13,Z$2:Z$9631,0) -> 169 | AB13: 25 | AC13: 12950 | AD13: 769 | AI13: 49 | AJ13: 71 | AK13: 7169 | AL13: 332 | AQ13: 62 | AR13: 65 | AS13: 8742 | AT13: 537
... A22: 399 | B22: 08 | C22: 08111921 | D22: 李霖浩 | E22: 男 | F22: 物生地 | G22: 2005270821 | H22: 409.38 | I22: 10407 | J22: 504 | K22: =SUM(N22+Q22+T22+W22+AB22) -> 270.38 | L22: =VLOOKUP(G22,[1]物理类!$F:$Q,12,FALSE) -> 10177 | M22: =RANK(K22,K$2:K$916,0) -> 462 | N22: 99.5 | O22: 14955 | P22: =RANK(N22,N$2:N$9631,0) -> 575 | Q22: 59 | R22: 10048 | S22: 312 | T22: 71.88 | U22: 14322 | V22: 547 | Z22: =SUM(T22+W22) -> 71.88 | AA22: =RANK(Z22,Z$2:Z$9631,0) -> 603 | AB22: 40 | AC22: 10281 | AD22: 403 | AI22: 55 | AJ22: 75 | AK22: 5678 | AL22: 186 | AQ22: 61 | AR22: 64 | AS22: 8948 | AT22: 551
A23: 400 | B23: 08 | C23: 08194422 | D23: 苏颖妍 | E23: 女 | F23: 物生地 | G23: 2005270822 | Z23: =SUM(T23+W23) -> 0 | AA23: =RANK(Z23,Z$2:Z$9631,0) -> 910
A24: 401 | B24: 08 | C24: 08064823 | D24: 陈佳铃 | E24: 女 | F24: 物生地 | G24: 2005270823 | H24: 414 | I24: 10161 | J24: 461 | K24: =SUM(N24+Q24+T24+W24+AB24) -> 266 | L24: =VLOOKUP(G24,[1]物理类!$F:$Q,12,FALSE) -> 10437 | M24: =RANK(K24,K$2:K$916,0) -> 511 | N24: 105 | O24: 10617 | P24: =RANK(N24,N$2:N$9631,0) -> 326 | Q24: 42 | R24: 14477 | S24: 604 | T24: 85 | U24: 10715 | V24: 274 | Z24: =SUM(T24+W24) -> 85 | AA24: =RANK(Z24,Z$2:Z$9631,0) -> 319 | AB24: 34 | AC24: 11425 | AD24: 548 | AI24: 48 | AJ24: 70 | AK24: 7403 | AL24: 358 | AQ24: 75 | AR24: 78 | AS24: 4148 | AT24: 210
A25: 402 | B25: 08 | C25: 08081124 | D25: 梁军博 | E25: 男 | F25: 物生地 | G25: 2005270824 | H25: 416 | I25: 10052 | J25: 447 | K25: =SUM(N25+Q25+T25+W25+AB25) -> 275 | L25: =VLOOKUP(G25,[1]物理类!$F:$Q,12,FALSE) -> 9895 | M25: =RANK(K25,K$2:K$916,0) -> 423 | N25: 93.5 | O25: 18120 | P25: =RANK(N25,N$2:N$9631,0) -> 772 | Q25: 41 | R25: 14746 | S25: 622 | T25: 92.5 | U25: 8522 | V25: 158 | Z25: =SUM(T25+W25) -> 92.5 | AA25: =RANK(Z25,Z$2:Z$9631,0) -> 193 | AB25: 48 | AC25: 8615 | AD25: 225 | AI25: 47 | AJ25: 69 | AK25: 7597 | AL25: 380 | AQ25: 70 | AR25: 72 | AS25: 6342 | AT25: 385
A26: 403 | B26: 08 | C26: 08210325 | D26: 孔繁铖 | E26: 男 | F26: 物生地 | G26: 2005270825 | H26: 419.75 | I26: 9852 | J26: 417 | K26: =SUM(N26+Q26+T26+W26+AB26) -> 280.75 | L26: =VLOOKUP(G26,[1]物理类!$F:$Q,12,FALSE) -> 9537 | M26: =RANK(K26,K$2:K$916,0) -> 366 | N26: 95.5 | O26: 17203 | P26: =RANK(N26,N$2:N$9631,0) -> 725 | Q26: 48 | R26: 12936 | S26: 481 | T26: 91.25 | U26: 8894 | V26: 176 | Z26: =SUM(T26+W26) -> 91.25 | AA26: =RANK(Z26,Z$2:Z$9631,0) -> 213 | AB26: 46 | AC26: 9052 | AD26: 261 | AI26: 53 | AJ26: 74 | AK26: 5937 | AL26: 211 | AQ26: 62 | AR26: 65 | AS26: 8742 | AT26: 537
A27: 404 | B27: 08 | C27: 08011326 | D27: 罗凯鑫 | E27: 男 | F27: 物生地 | G27: 2005270826 | H27: 365.75 | I27: 12350 | J27: 774 | K27: =SUM(N27+Q27+T27+W27+AB27) -> 229.75 | L27: =VLOOKUP(G27,[1]物理类!$F:$Q,12,FALSE) -> 12272 | M27: =RANK(K27,K$2:K$916,0) -> 786 | N27: 99 | O27: 15281 | P27: =RANK(N27,N$2:N$9631,0) -> 591 | Q27: 30 | R27: 17706 | S27: 780 | T27: 73.75 | U27: 13842 | V27: 513 | Z27: =SUM(T27+W27) -> 73.75 | AA27: =RANK(Z27,Z$2:Z$9631,0) -> 568 | AB27: 27 | AC27: 12644 | AD27: 728 | AI27: 42 | AJ27: 67 | AK27: 8374 | AL27: 465 | AQ27: 67 | AR27: 69 | AS27: 7451 | AT27: 463
A28: 405 | B28: 08 | C28: 08161127 | D28: 冼晓婷 | E28: 女 | F28: 物生地 | G28: 2005270827 | H28: 409.88 | I28: 10382 | J28: 497 | K28: =SUM(N28+Q28+T28+W28+AB28) -> 252.88 | L28: =VLOOKUP(G28,[1]物理类!$F:$Q,12,FALSE) -> 11182 | M28: =RANK(K28,K$2:K$916,0) -> 615 | N28: 92.5 | O28: 18517 | P28: =RANK(N28,N$2:N$9631,0) -> 796 | Q28: 46 | R28: 13454 | S28: 525 | T28: 89.38 | U28: 9437 | V28: 196 | Z28: =SUM(T28+W28) -> 89.38 | AA28: =RANK(Z28,Z$2:Z$9631,0) -> 236 | AB28: 25 | AC28: 12950 | AD28: 769 | AI28: 51 | AJ28: 72 | AK28: 6673 | AL28: 279 | AQ28: 81 | AR28: 85 | AS28: 1346 | AT28: 39
A29: 406 | B29: 08 | C29: 08103128 | D29: 邓祥辉 | E29: 男 | F29: 物生地 | G29: 2005270828 | H29: 412.38 | I29: 10257 | J29: 473 | K29: =SUM(N29+Q29+T29+W29+AB29) -> 276.38 | L29: =VLOOKUP(G29,[1]物理类!$F:$Q,12,FALSE) -> 9810 | M29: =RANK(K29,K$2:K$916,0) -> 406 | N29: 101 | O29: 13862 | P29: =RANK(N29,N$2:N$9631,0) -> 499 | Q29: 44 | R29: 13946 | S29: 565 | T29: 74.38 | U29: 13667 | V29: 506 | Z29: =SUM(T29+W29) -> 74.38 | AA29: =RANK(Z29,Z$2:Z$9631,0) -> 561 | AB29: 57 | AC29: 6643 | AD29: 96 | AI29: 45 | AJ29: 68 | AK29: 7991 | AL29: 425 | AQ29: 66 | AR29: 68 | AS29: 7744 | AT29: 481
A30: 407 | B30: 08 | C30: 08041629 | D30: 林鹏程 | E30: 男 | F30: 物生地 | G30: 2005270829 | H30: 302.88 | I30: 13948 | J30: 904 | K30: =SUM(N30+Q30+T30+W30+AB30) -> 166.88 | L30: =VLOOKUP(G30,[1]物理类!$F:$Q,12,FALSE) -> 13857 | M30: =RANK(K30,K$2:K$916,0) -> 907 | N30: 85 | O30: 20433 | P30: =RANK(N30,N$2:N$9631,0) -> 880 | Q30: 10 | R30: 21360 | S30: 904 | T30: 51.88 | U30: 18226 | V30: 813 | Z30: =SUM(T30+W30) -> 51.88 | AA30: =RANK(Z30,Z$2:Z$9631,0) -> 871 | AB30: 20 | AC30: 13637 | AD30: 850 | AI30: 38 | AJ30: 64 | AK30: 9144 | AL30: 559 | AQ30: 70 | AR30: 72 | AS30: 6342 | AT30: 385
A31: 408 | B31: 08 | C31: 08063630 | D31: 高子涵 | E31: 女 | F31: 物生地 | G31: 2005270830 | H31: 348 | I31: 12965 | J31: 851 | K31: =SUM(N31+Q31+T31+W31+AB31) -> 207 | L31: =VLOOKUP(G31,[1]物理类!$F:$Q,12,FALSE) -> 13062 | M31: =RANK(K31,K$2:K$916,0) -> 872 | N31: 92.5 | O31: 18517 | P31: =RANK(N31,N$2:N$9631,0) -> 796 | Q31: 28 | R31: 18213 | S31: 804 | T31: 52.5 | U31: 18139 | V31: 811 | Z31: =SUM(T31+W31) -> 52.5 | AA31: =RANK(Z31,Z$2:Z$9631,0) -> 869 | AB31: 34 | AC31: 11425 | AD31: 548 | AI31: 40 | AJ31: 65 | AK31: 8848 | AL31: 526 | AQ31: 73 | AR31: 76 | AS31: 5040 | AT31: 283
A32: 409 | B32: 08 | C32: 08044431 | D32: 李心悦 | E32: 女 | F32: 物生地 | G32: 2005270831 | H32: 407.88 | I32: 10485 | J32: 517 | K32: =SUM(N32+Q32+T32+W32+AB32) -> 256.88 | L32: =VLOOKUP(G32,[1]物理类!$F:$Q,12,FALSE) -> 10962 | M32: =RANK(K32,K$2:K$916,0) -> 582 | N32: 109.5 | O32: 6880 | P32: =RANK(N32,N$2:N$9631,0) -> 152 | Q32: 46 | R32: 13454 | S32: 525 | T32: 64.38 | U32: 16034 | V32: 697 | Z32: =SUM(T32+W32) -> 64.38 | AA32: =RANK(Z32,Z$2:Z$9631,0) -> 755 | AB32: 37 | AC32: 10849 | AD32: 463 | AI32: 55 | AJ32: 75 | AK32: 5678 | AL32: 186 | AQ32: 73 | AR32: 76 | AS32: 5040 | AT32: 283
A33: 410 | B33: 08 | C33: 08131832 | D33: 黄善 | E33: 男 | F33: 物生地 | G33: 2005270832 | H33: 411.13 | I33: 10318 | J33: 486 | K33: =SUM(N33+Q33+T33+W33+AB33) -> 259.13 | L33: =VLOOKUP(G33,[1]物理类!$F:$Q,12,FALSE) -> 10836 | M33: =RANK(K33,K$2:K$916,0) -> 565 | N33: 110 | O33: 6475 | P33: =RANK(N33,N$2:N$9631,0) -> 140 | Q33: 40 | R33: 15025 | S33: 642 | T33: 78.13 | U33: 12671 | V33: 426 | Z33: =SUM(T33+W33) -> 78.13 | AA33: =RANK(Z33,Z$2:Z$9631,0) -> 478 | AB33: 31 | AC33: 11968 | AD33: 629 | AI33: 54 | AJ33: 74 | AK33: 5937 | AL33: 211 | AQ33: 75 | AR33: 78 | AS33: 4148 | AT33: 210
A34: 411 | B34: 08 | C34: 08034233 | D34: 梁浩 | E34: 男 | F34: 物生地 | G34: 2005270833 | H34: 372.75 | I34: 12079 | J34: 746 | K34: =SUM(N34+Q34+T34+W34+AB34) -> 223.75 | L34: =VLOOKUP(G34,[1]物理类!$F:$Q,12,FALSE) -> 12486 | M34: =RANK(K34,K$2:K$916,0) -> 811 | N34: 94 | O34: 17891 | P34: =RANK(N34,N$2:N$9631,0) -> 760 | Q34: 0 | R34: 21720 | S34: 909 | T34: 98.75 | U34: 6736 | V34: 83 | Z34: =SUM(T34+W34) -> 98.75 | AA34: =RANK(Z34,Z$2:Z$9631,0) -> 108 | AB34: 31 | AC34: 11968 | AD34: 629 | AI34: 45 | AJ34: 68 | AK34: 7991 | AL34: 425 | AQ34: 77 | AR34: 81 | AS34: 3262 | AT34: 150
A35: 412 | B35: 08 | C35: 08183934 | D35: 何泽恩 | E35: 男 | F35: 物生地 | G35: 2005270834 | H35: 364.38 | I35: 12404 | J35: 783 | K35: =SUM(N35+Q35+T35+W35+AB35) -> 217.38 | L35: =VLOOKUP(G35,[1]物理类!$F:$Q,12,FALSE) -> 12746 | M35: =RANK(K35,K$2:K$916,0) -> 841 | N35: 110.5 | O35: 6084 | P35: =RANK(N35,N$2:N$9631,0) -> 121 | Q35: 21 | R35: 19866 | S35: 870 | T35: 66.88 | U35: 15469 | V35: 656 | Z35: =SUM(T35+W35) -> 66.88 | AA35: =RANK(Z35,Z$2:Z$9631,0) -> 714 | AB35: 19 | AC35: 13758 | AD35: 862 | AI35: 42 | AJ35: 67 | AK35: 8374 | AL35: 465 | AQ35: 76 | AR35: 80 | AS35: 3690 | AT35: 180
... A55: 432 | B55: 08 | C55: 08034554 | D55: 黄斌 | E55: 男 | F55: 物生地 | G55: 2005270854 | H55: 357 | I55: 12638 | J55: 817 | K55: =SUM(N55+Q55+T55+W55+AB55) -> 219 | L55: =VLOOKUP(G55,[1]物理类!$F:$Q,12,FALSE) -> 12689 | M55: =RANK(K55,K$2:K$916,0) -> 839 | N55: 93.5 | O55: 18120 | P55: =RANK(N55,N$2:N$9631,0) -> 772 | Q55: 15 | R55: 20820 | S55: 896 | T55: 67.5 | U55: 15336 | V55: 646 | Z55: =SUM(T55+W55) -> 67.5 | AA55: =RANK(Z55,Z$2:Z$9631,0) -> 703 | AB55: 43 | AC55: 9674 | AD55: 324 | AI55: 35 | AJ55: 62 | AK55: 9471 | AL55: 589 | AQ55: 73 | AR55: 76 | AS55: 5040 | AT55: 283
A56: 434 | B56: 09 | C56: 09131401 | D56: 杜镇廷 | E56: 男 | F56: 物生政 | G56: 2005270901 | H56: 544.25 | I56: 2897 | J56: 12 | K56: =SUM(N56+Q56+T56+W56+AB56) -> 378.25 | L56: =VLOOKUP(G56,[1]物理类!$F:$Q,12,FALSE) -> 2885 | M56: =RANK(K56,K$2:K$916,0) -> 11 | N56: 111.5 | O56: 5395 | P56: =RANK(N56,N$2:N$9631,0) -> 102 | Q56: 83 | R56: 4317 | S56: 58 | T56: 118.75 | U56: 2009 | V56: 6 | Z56: =SUM(T56+W56) -> 118.75 | AA56: =RANK(Z56,Z$2:Z$9631,0) -> 13 | AB56: 65 | AC56: 4907 | AD56: 42 | AI56: 69 | AJ56: 84 | AK56: 2318 | AL56: 21 | AM56: 59 | AN56: 82 | AO56: 2554 | AP56: 118
A57: 435 | B57: 09 | C57: 09110302 | D57: 张艺珊 | E57: 女 | F57: 物生政 | G57: 2005270902 | H57: 417.63 | I57: 9960 | J57: 432 | K57: =SUM(N57+Q57+T57+W57+AB57) -> 269.63 | L57: =VLOOKUP(G57,[1]物理类!$F:$Q,12,FALSE) -> 10227 | M57: =RANK(K57,K$2:K$916,0) -> 470 | N57: 105.5 | O57: 10233 | P57: =RANK(N57,N$2:N$9631,0) -> 306 | Q57: 40 | R57: 15025 | S57: 642 | T57: 83.13 | U57: 11258 | V57: 316 | Z57: =SUM(T57+W57) -> 83.13 | AA57: =RANK(Z57,Z$2:Z$9631,0) -> 362 | AB57: 41 | AC57: 10092 | AD57: 378 | AI57: 52 | AJ57: 73 | AK57: 6415 | AL57: 262 | AM57: 52 | AN57: 75 | AO57: 4661 | AP57: 296
A58: 436 | B58: 09 | C58: 09070603 | D58: 梁思睿 | E58: 女 | F58: 物生政 | G58: 2005270903 | H58: 426 | I58: 9533 | J58: 364 | K58: =SUM(N58+Q58+T58+W58+AB58) -> 275 | L58: =VLOOKUP(G58,[1]物理类!$F:$Q,12,FALSE) -> 9895 | M58: =RANK(K58,K$2:K$916,0) -> 423 | N58: 100 | O58: 14571 | P58: =RANK(N58,N$2:N$9631,0) -> 546 | Q58: 43 | R58: 14226 | S58: 583 | T58: 100 | U58: 6407 | V58: 69 | Z58: =SUM(T58+W58) -> 100 | AA58: =RANK(Z58,Z$2:Z$9631,0) -> 93 | AB58: 32 | AC58: 11800 | AD58: 607 | AI58: 48 | AJ58: 70 | AK58: 7403 | AL58: 358 | AM58: 58 | AN58: 81 | AO58: 2853 | AP58: 142
A59: 437 | B59: 09 | C59: 09181804 | D59: 陈育瑶 | E59: 女 | F59: 物生政 | G59: 2005270904 | H59: 436.25 | I59: 8995 | J59: 300 | K59: =SUM(N59+Q59+T59+W59+AB59) -> 284.25 | L59: =VLOOKUP(G59,[1]物理类!$F:$Q,12,FALSE) -> 9333 | M59: =RANK(K59,K$2:K$916,0) -> 347 | N59: 99.5 | O59: 14955 | P59: =RANK(N59,N$2:N$9631,0) -> 575 | Q59: 67 | R59: 8089 | S59: 190 | T59: 93.75 | U59: 8156 | V59: 143 | Z59: =SUM(T59+W59) -> 93.75 | AA59: =RANK(Z59,Z$2:Z$9631,0) -> 178 | AB59: 24 | AC59: 13102 | AD59: 785 | AI59: 56 | AJ59: 76 | AK59: 5201 | AL59: 147 | AM59: 53 | AN59: 76 | AO59: 4357 | AP59: 270
A60: 438 | B60: 09 | C60: 09040605 | D60: 谭语涵 | E60: 女 | F60: 物生政 | G60: 2005270905 | H60: 452.75 | I60: 8064 | J60: 188 | K60: =SUM(N60+Q60+T60+W60+AB60) -> 297.75 | L60: =VLOOKUP(G60,[1]物理类!$F:$Q,12,FALSE) -> 8488 | M60: =RANK(K60,K$2:K$916,0) -> 244 | N60: 104.5 | O60: 11039 | P60: =RANK(N60,N$2:N$9631,0) -> 356 | Q60: 53 | R60: 11613 | S60: 400 | T60: 101.25 | U60: 6084 | V60: 59 | Z60: =SUM(T60+W60) -> 101.25 | AA60: =RANK(Z60,Z$2:Z$9631,0) -> 81 | AB60: 39 | AC60: 10485 | AD60: 424 | AI60: 59 | AJ60: 77 | AK60: 4706 | AL60: 125 | AM60: 55 | AN60: 78 | AO60: 3738 | AP60: 223
A61: 439 | B61: 09 | C61: 09112106 | D61: 郑可馨 | E61: 女 | F61: 物生政 | G61: 2005270906 | H61: 380.75 | I61: 11746 | J61: 703 | K61: =SUM(N61+Q61+T61+W61+AB61) -> 237.75 | L61: =VLOOKUP(G61,[1]物理类!$F:$Q,12,FALSE) -> 11933 | M61: =RANK(K61,K$2:K$916,0) -> 739 | N61: 101 | O61: 13862 | P61: =RANK(N61,N$2:N$9631,0) -> 499 | Q61: 27 | R61: 18461 | S61: 819 | T61: 78.75 | U61: 12496 | V61: 407 | Z61: =SUM(T61+W61) -> 78.75 | AA61: =RANK(Z61,Z$2:Z$9631,0) -> 457 | AB61: 31 | AC61: 11968 | AD61: 629 | AI61: 43 | AJ61: 67 | AK61: 8374 | AL61: 465 | AM61: 53 | AN61: 76 | AO61: 4357 | AP61: 270
A62: 440 | B62: 09 | C62: 09010507 | D62: 林浴菁 | E62: 女 | F62: 物生政 | G62: 2005270907 | H62: 442.25 | I62: 8665 | J62: 251 | K62: =SUM(N62+Q62+T62+W62+AB62) -> 290.25 | L62: =VLOOKUP(G62,[1]物理类!$F:$Q,12,FALSE) -> 8960 | M62: =RANK(K62,K$2:K$916,0) -> 300 | N62: 102.5 | O62: 12724 | P62: =RANK(N62,N$2:N$9631,0) -> 433 | Q62: 58 | R62: 10302 | S62: 324 | T62: 78.75 | U62: 12496 | V62: 407 | Z62: =SUM(T62+W62) -> 78.75 | AA62: =RANK(Z62,Z$2:Z$9631,0) -> 457 | AB62: 51 | AC62: 7998 | AD62: 170 | AI62: 62 | AJ62: 79 | AK62: 3903 | AL62: 69 | AM62: 49 | AN62: 73 | AO62: 5563 | AP62: 361
A63: 441 | B63: 09 | C63: 09111708 | D63: 杨柳 | E63: 女 | F63: 物生政 | G63: 2005270908 | H63: 389.63 | I63: 11356 | J63: 643 | K63: =SUM(N63+Q63+T63+W63+AB63) -> 235.63 | L63: =VLOOKUP(G63,[1]物理类!$F:$Q,12,FALSE) -> 12021 | M63: =RANK(K63,K$2:K$916,0) -> 753 | N63: 108 | O63: 8077 | P63: =RANK(N63,N$2:N$9631,0) -> 205 | Q63: 28 | R63: 18213 | S63: 804 | T63: 80.63 | U63: 11983 | V63: 352 | Z63: =SUM(T63+W63) -> 80.63 | AA63: =RANK(Z63,Z$2:Z$9631,0) -> 402 | AB63: 19 | AC63: 13758 | AD63: 862 | AI63: 47 | AJ63: 69 | AK63: 7597 | AL63: 380 | AM63: 63 | AN63: 85 | AO63: 1241 | AP63: 39
A64: 442 | B64: 09 | C64: 09051509 | D64: 蔡沛滢 | E64: 女 | F64: 物生政 | G64: 2005270909 | H64: 503.5 | I64: 5147 | J64: 35 | K64: =SUM(N64+Q64+T64+W64+AB64) -> 334.5 | L64: =VLOOKUP(G64,[1]物理类!$F:$Q,12,FALSE) -> 5864 | M64: =RANK(K64,K$2:K$916,0) -> 61 | N64: 110 | O64: 6475 | P64: =RANK(N64,N$2:N$9631,0) -> 140 | Q64: 74 | R64: 6408 | S64: 117 | T64: 92.5 | U64: 8522 | V64: 158 | Z64: =SUM(T64+W64) -> 92.5 | AA64: =RANK(Z64,Z$2:Z$9631,0) -> 193 | AB64: 58 | AC64: 6423 | AD64: 89 | AI64: 60 | AJ64: 78 | AK64: 4431 | AL64: 104 | AM64: 75 | AN64: 91 | AO64: 97 | AP64: 1
A65: 443 | B65: 09 | C65: 09083210 | D65: 曾星语 | E65: 女 | F65: 物生政 | G65: 2005270910 | H65: 380.75 | I65: 11746 | J65: 703 | K65: =SUM(N65+Q65+T65+W65+AB65) -> 222.75 | L65: =VLOOKUP(G65,[1]物理类!$F:$Q,12,FALSE) -> 12524 | M65: =RANK(K65,K$2:K$916,0) -> 816 | N65: 100 | O65: 14571 | P65: =RANK(N65,N$2:N$9631,0) -> 546 | Q65: 52 | R65: 11878 | S65: 414 | T65: 53.75 | U65: 17953 | V65: 798 | Z65: =SUM(T65+W65) -> 53.75 | AA65: =RANK(Z65,Z$2:Z$9631,0) -> 856 | AB65: 17 | AC65: 13947 | AD65: 880 | AI65: 61 | AJ65: 79 | AK65: 3903 | AL65: 69 | AM65: 56 | AN65: 79 | AO65: 3435 | AP65: 191
A66: 444 | B66: 09 | C66: 09034111 | D66: 陈嘉乐 | E66: 男 | F66: 物生政 | G66: 2005270911 | H66: 420.5 | I66: 9807 | J66: 406 | K66: =SUM(N66+Q66+T66+W66+AB66) -> 274.5 | L66: =VLOOKUP(G66,[1]物理类!$F:$Q,12,FALSE) -> 9926 | M66: =RANK(K66,K$2:K$916,0) -> 430 | N66: 101 | O66: 13862 | P66: =RANK(N66,N$2:N$9631,0) -> 499 | Q66: 51 | R66: 12144 | S66: 437 | T66: 82.5 | U66: 11449 | V66: 331 | Z66: =SUM(T66+W66) -> 82.5 | AA66: =RANK(Z66,Z$2:Z$9631,0) -> 378 | AB66: 40 | AC66: 10281 | AD66: 403 | AI66: 47 | AJ66: 69 | AK66: 7597 | AL66: 380 | AM66: 54 | AN66: 77 | AO66: 4065 | AP66: 246
A67: 445 | B67: 09 | C67: 09033912 | D67: 陈锦怡 | E67: 女 | F67: 物生政 | G67: 2005270912 | H67: 415.63 | I67: 10076 | J67: 450 | K67: =SUM(N67+Q67+T67+W67+AB67) -> 272.63 | L67: =VLOOKUP(G67,[1]物理类!$F:$Q,12,FALSE) -> 10036 | M67: =RANK(K67,K$2:K$916,0) -> 447 | N67: 106 | O67: 9791 | P67: =RANK(N67,N$2:N$9631,0) -> 284 | Q67: 42 | R67: 14477 | S67: 604 | T67: 95.63 | U67: 7627 | V67: 123 | Z67: =SUM(T67+W67) -> 95.63 | AA67: =RANK(Z67,Z$2:Z$9631,0) -> 156 | AB67: 29 | AC67: 12322 | AD67: 679 | AI67: 47 | AJ67: 69 | AK67: 7597 | AL67: 380 | AM67: 50 | AN67: 74 | AO67: 5257 | AP67: 337
...
